<?xml version="1.0" ?>
<robot name="rarm_5" xmlns:xacro="http://ros.org/wiki/xacro">

  <link name="world"/>

  <joint name="world_joint" type="fixed">
    <parent link="world"/>
    <child link="base_link"/>
    <origin xyz="0 0 0" rpy="0 0 0"/>
  </joint>

  <link name="base_link">
    <inertial>
      <origin xyz="0.0014586 0.038724 -0.0014254" rpy="0 0 0" />
      <mass value="500.7738" />
      <inertia ixx="3.6438" ixy="-0.0034695" ixz="-0.079994" iyy="6.6456" iyz="0.0041166" izz="3.6402" />
    </inertial>
    <visual>
      <origin xyz="0 0 0" rpy="0 0 0" />
      <geometry>
        <mesh filename="package://urc_arm_description/meshes/base_link.STL" />
      </geometry>
      <material name="dark_grey"><color rgba="0.2 0.2 0.2 1" /></material>
    </visual>
    <collision>
      <origin xyz="0 0 0" rpy="0 0 0" />
      <geometry>
        <mesh filename="package://urc_arm_description/meshes/base_link.STL" />
      </geometry>
    </collision>
  </link>

  <link name="link_1">
    <inertial>
      <origin xyz="0 0.077 0" rpy="0 0 0" />
      <mass value="2.019" />
      <inertia ixx="0.01" ixy="0" ixz="0" iyy="0.006" iyz="0" izz="0.012" />
    </inertial>
    <visual>
      <origin xyz="0 0 0" rpy="0 0 0" />
      <geometry>
        <mesh filename="package://urc_arm_description/meshes/link_1.STL" />
      </geometry>
    </visual>
    <collision>
      <origin xyz="0 0 0" rpy="0 0 0" />
      <geometry>
        <mesh filename="package://urc_arm_description/meshes/link_1.STL" />
      </geometry>
    </collision>
  </link>

  <joint name="joint_1" type="continuous">
    <origin xyz="0 0 0.085" rpy="1.5708 0 1.5708" />
    <parent link="base_link" />
    <child link="link_1" />
    <axis xyz="0 1 0" />
  </joint>

  <link name="link_2">
    <inertial>
      <origin xyz="-0.147 0.036 0" rpy="0 0 0" />
      <mass value="0.975" />
      <inertia ixx="0.0005" ixy="0" ixz="0" iyy="0.018" iyz="0" izz="0.018" />
    </inertial>
    <visual>
      <origin xyz="0 0 0" rpy="0 0 0" />
      <geometry>
        <mesh filename="package://urc_arm_description/meshes/link_2.STL" />
      </geometry>
    </visual>
    <collision>
      <origin xyz="0 0 0" rpy="0 0 0" />
      <geometry>
        <mesh filename="package://urc_arm_description/meshes/link_2.STL" />
      </geometry>
    </collision>
  </link>

  <joint name="joint_2" type="continuous">
    <origin xyz="0 0.197 0" rpy="-1.5708 0 0.034375" />
    <parent link="link_1" />
    <child link="link_2" />
    <axis xyz="0 -1 0" />
  </joint>

  <link name="link_3">
    <inertial>
      <origin xyz="0.017 0 0.068" rpy="0 0 0" />
      <mass value="1.187" />
      <inertia ixx="0.006" ixy="0" ixz="0" iyy="0.006" iyz="0" izz="0.001" />
    </inertial>
    <visual>
      <origin xyz="0 0 0" rpy="0 0 0" />
      <geometry>
        <mesh filename="package://urc_arm_description/meshes/link_3.STL" />
      </geometry>
    </visual>
    <collision>
      <origin xyz="0 0 0" rpy="0 0 0" />
      <geometry>
        <mesh filename="package://urc_arm_description/meshes/link_3.STL" />
      </geometry>
    </collision>
  </link>

  <joint name="joint_3" type="continuous">
    <origin xyz="-0.35 0 0" rpy="-0.034375 0 -1.5708" />
    <parent link="link_2" />
    <child link="link_3" />
    <axis xyz="1 0 0" />
  </joint>

  <link name="link_4">
    <inertial>
      <origin xyz="0 0 -0.084" rpy="0 0 0" />
      <mass value="0.495" />
      <inertia ixx="0.001" ixy="0" ixz="0" iyy="0.001" iyz="0" izz="0.0005" />
    </inertial>
    <visual>
      <origin xyz="0 0 0" rpy="0 0 0" />
      <geometry>
        <mesh filename="package://urc_arm_description/meshes/link_4.STL" />
      </geometry>
    </visual>
    <collision>
      <origin xyz="0 0 0" rpy="0 0 0" />
      <geometry>
        <mesh filename="package://urc_arm_description/meshes/link_4.STL" />
      </geometry>
    </collision>
  </link>

  <joint name="joint_4" type="continuous">
    <origin xyz="0.0175 0 0.23901" rpy="3.1416 0 0" />
    <parent link="link_3" />
    <child link="link_4" />
    <axis xyz="0 0 1" />
  </joint>

  <link name="link_5">
    <inertial>
      <origin xyz="0 -0.064 0" rpy="0 0 0" />
      <mass value="0.401" />
      <inertia ixx="0.0006" ixy="0" ixz="0" iyy="0.0002" iyz="0" izz="0.0006" />
    </inertial>
    <visual>
      <origin xyz="0 0 0" rpy="0 0 0" />
      <geometry>
        <mesh filename="package://urc_arm_description/meshes/link_5.STL" />
      </geometry>
    </visual>
    <collision>
      <origin xyz="0 0 0" rpy="0 0 0" />
      <geometry>
        <mesh filename="package://urc_arm_description/meshes/link_5.STL" />
      </geometry>
    </collision>
  </link>

  <joint name="joint_5" type="continuous">
    <origin xyz="0 0 -0.135" rpy="3.1416 0 0" />
    <parent link="link_4" />
    <child link="link_5" />
    <axis xyz="1 0 0" />
  </joint>

  <gazebo reference="link_1"><self_collide>false</self_collide></gazebo>
  <gazebo reference="link_2"><self_collide>false</self_collide></gazebo>
  <gazebo reference="link_3"><self_collide>false</self_collide></gazebo>
  <gazebo reference="link_4"><self_collide>false</self_collide></gazebo>
  <gazebo reference="link_5"><self_collide>false</self_collide></gazebo>

  <ros2_control name="GazeboSystem" type="system">
    <hardware>
      <plugin>gazebo_ros2_control/GazeboSystem</plugin>
    </hardware>
    <joint name="joint_1">
      <command_interface name="position"/><state_interface name="position"/><state_interface name="velocity"/>
    </joint>
    <joint name="joint_2">
      <command_interface name="position"/><state_interface name="position"/><state_interface name="velocity"/>
    </joint>
    <joint name="joint_3">
      <command_interface name="position"/><state_interface name="position"/><state_interface name="velocity"/>
    </joint>
    <joint name="joint_4">
      <command_interface name="position"/><state_interface name="position"/><state_interface name="velocity"/>
    </joint>
    <joint name="joint_5">
      <command_interface name="position"/><state_interface name="position"/><state_interface name="velocity"/>
    </joint>
  </ros2_control>

  <gazebo reference="link_5">
    <sensor name="yolo_camera" type="camera">
      <camera>
        <horizontal_fov>1.3962634</horizontal_fov>
        <image>
          <width>1024</width>
          <height>1024</height>
          <format>R8G8B8</format>
        </image>
        <clip><near>0.02</near><far>300</far></clip>
      </camera>
      <always_on>1</always_on>
      <update_rate>30</update_rate>
      <visualize>true</visualize>
      <topic>camera/image_raw</topic>
    </sensor>
  </gazebo>

</robot>
