<?xml version="1.0" ?>
<robot name="urc_arm">

  <material name="orange"><color rgba="1.0 0.5 0.0 1.0"/></material>
  <material name="grey"><color rgba="0.2 0.2 0.2 1.0"/></material>

  <link name="base_link">
    <visual>
      <geometry><cylinder length="0.1" radius="0.1"/></geometry>
      <material name="grey"/>
    </visual>
    <collision>
      <geometry><cylinder length="0.1" radius="0.1"/></geometry>
    </collision>
    <inertial>
      <mass value="1.0"/>
      <inertia ixx="0.01" ixy="0" ixz="0" iyy="0.01" iyz="0" izz="0.01"/>
    </inertial>
  </link>

  <joint name="joint_1" type="revolute">
    <parent link="base_link"/>
    <child link="shoulder_link"/>
    <origin rpy="0 0 0" xyz="0 0 0.05"/>
    <axis xyz="0 0 1"/>
    <limit effort="100" lower="-3.14" upper="3.14" velocity="1.0"/>
  </joint>

  <link name="shoulder_link">
    <visual>
      <geometry><box size="0.1 0.1 0.1"/></geometry>
      <material name="orange"/>
    </visual>
    <collision>
      <geometry><box size="0.1 0.1 0.1"/></geometry>
    </collision>
    <inertial>
      <mass value="0.5"/>
      <inertia ixx="0.001" ixy="0" ixz="0" iyy="0.001" iyz="0" izz="0.001"/>
    </inertial>
  </link>

  <joint name="joint_2" type="revolute">
    <parent link="shoulder_link"/>
    <child link="upper_arm_link"/>
    <origin rpy="0 0 0" xyz="0 0 0.1"/>
    <axis xyz="0 1 0"/>
    <limit effort="200" lower="-1.57" upper="1.57" velocity="1.0"/>
  </joint>

  <link name="upper_arm_link">
    <visual>
      <origin rpy="0 0 0" xyz="0 0 0.2"/>
      <geometry><cylinder length="0.4" radius="0.05"/></geometry>
      <material name="grey"/>
    </visual>
    <collision>
      <origin rpy="0 0 0" xyz="0 0 0.2"/>
      <geometry><cylinder length="0.4" radius="0.05"/></geometry>
    </collision>
    <inertial>
      <origin xyz="0 0 0.2"/>
      <mass value="0.8"/>
      <inertia ixx="0.01" ixy="0" ixz="0" iyy="0.01" iyz="0" izz="0.001"/>
    </inertial>
  </link>

  <joint name="joint_3" type="revolute">
    <parent link="upper_arm_link"/>
    <child link="forearm_link"/>
    <origin rpy="0 0 0" xyz="0 0 0.4"/>
    <axis xyz="0 1 0"/>
    <limit effort="150" lower="-2.5" upper="2.5" velocity="1.0"/>
  </joint>

  <link name="forearm_link">
    <visual>
      <origin rpy="0 0 0" xyz="0 0 0.175"/>
      <geometry><cylinder length="0.35" radius="0.04"/></geometry>
      <material name="orange"/>
    </visual>
    <collision>
      <origin rpy="0 0 0" xyz="0 0 0.175"/>
      <geometry><cylinder length="0.35" radius="0.04"/></geometry>
    </collision>
    <inertial>
      <origin xyz="0 0 0.175"/>
      <mass value="0.6"/>
      <inertia ixx="0.005" ixy="0" ixz="0" iyy="0.005" iyz="0" izz="0.001"/>
    </inertial>
  </link>

  <joint name="joint_4" type="revolute">
    <parent link="forearm_link"/>
    <child link="wrist_link"/>
    <origin rpy="0 0 0" xyz="0 0 0.35"/>
    <axis xyz="0 1 0"/>
    <limit effort="50" lower="-1.57" upper="1.57" velocity="1.5"/>
  </joint>

  <link name="wrist_link">
    <visual>
      <geometry><box size="0.05 0.08 0.05"/></geometry>
      <material name="grey"/>
    </visual>
    <collision>
      <geometry><box size="0.05 0.08 0.05"/></geometry>
    </collision>
    <inertial>
      <mass value="0.2"/>
      <inertia ixx="0.0005" ixy="0" ixz="0" iyy="0.0005" iyz="0" izz="0.0005"/>
    </inertial>
  </link>

  <joint name="joint_5" type="revolute">
    <parent link="wrist_link"/>
    <child link="end_effector_link"/>
    <origin rpy="0 0 0" xyz="0 0 0.05"/>
    <axis xyz="1 0 0"/>
    <limit effort="20" lower="-3.14" upper="3.14" velocity="2.0"/>
  </joint>

  <link name="end_effector_link">
    <visual>
      <origin rpy="0 0 0" xyz="0 0 0.075"/>
      <geometry><box size="0.03 0.1 0.15"/></geometry>
      <material name="orange"/>
    </visual>
    <collision>
      <origin rpy="0 0 0" xyz="0 0 0.075"/>
      <geometry><box size="0.03 0.1 0.15"/></geometry>
    </collision>
    <inertial>
      <origin xyz="0 0 0.075"/>
      <mass value="0.3"/>
      <inertia ixx="0.001" ixy="0" ixz="0" iyy="0.001" iyz="0" izz="0.001"/>
    </inertial>
  </link>

  <joint name="camera_joint" type="fixed">
    <parent link="end_effector_link"/>
    <child link="camera_link"/>
    <origin rpy="0 -1.57 0" xyz="0.03 0 0.05"/>
  </joint>
  
  <link name="camera_link">
    <visual>
      <geometry><box size="0.001 0.001 0.001"/></geometry>
    </visual>
    <collision>
      <geometry><box size="0.001 0.001 0.001"/></geometry>
    </collision>
    <inertial>
      <mass value="0.01"/>
      <inertia ixx="1e-6" ixy="0" ixz="0" iyy="1e-6" iyz="0" izz="1e-6"/>
    </inertial>
  </link>

  <joint name="tof_joint" type="fixed">
    <parent link="end_effector_link"/>
    <child link="tof_link"/>
    <origin rpy="0 -1.57 0" xyz="0.03 0.02 0.05"/>
  </joint>

  <link name="tof_link">
    <visual>
      <geometry><box size="0.001 0.001 0.001"/></geometry>
    </visual>
    <collision>
      <geometry><box size="0.001 0.001 0.001"/></geometry>
    </collision>
    <inertial>
      <mass value="0.01"/>
      <inertia ixx="1e-6" ixy="0" ixz="0" iyy="1e-6" iyz="0" izz="1e-6"/>
    </inertial>
  </link>

</robot>